Workbook

Sheet score
A1: タイムスタンプ | B1: Student Name | C1: Cat.1 Score | D1: Cat.2 Score | E1: Cat.3 Score | F1: Cat.4 Score | G1: Cat.5 Score | H1: Cat.6 Score | I1: Cat.7 Score | J1: Cat.8 Score | K1: Listening | L1: Writing | M1: Speaking | N1: Reading | O1: Attitude
B2: Kokoro Teramura | C2: 4 | D2: 4 | E2: 5 | F2: 5 | G2: 5 | H2: 4 | I2: 4 | J2: 5 | K2: 5 | L2: 5 | M2: 4 | N2: 5 | O2: 5
E3: 2 | J3: 4 | K3: 5
A4: Level | B4: 18

Sheet printable
B2: 総合評価 | G2: =score!B2 -> Kokoro Teramura | K2: レッスンの理解度 | P2: ="Lv."&score!B4 -> Lv.18 | S2: PASS
K4: =IF(score!B4=30,category!B1,IF(score!B4=29,category!B2,IF(score!B4=28,category!B3,IF(score!B4=27,category!B4,IF(score!B4=26,category!B5,IF(score!B4=25,category!B6,IF(score!B4=24,category!B7,IF(score!B4=23,category!B8,IF(score!B4=22,category!B9,IF(score!B4=21,category!B10,IF(score!B4=20,category!B11,IF(score!B4=19,category!B12,IF(score!B4=18,category!B13,IF(score!B4=17,category!B14,IF(score!B4=16,category!B15,IF(score!B4=15,category!B16,IF(score!B4=14,category!B17,IF(score!B4=13,category!B18,IF(score!B4=12,category!B19,IF(score!B4=11,category!B20,IF(score!B4=10,category!B21,IF(score!B4=9,category!B22,IF(score!B4=8,category!B23,IF(score!B4=7,category!B24,IF(score!B4=6,category!B25,IF(score!B4=5,category!B26,IF(score!B4=4,category!B27,IF(score!B4=3,category!B28,IF(score!B4=2,category!B29,IF(score!B4=1,category!B30,"")))))))))))))))))))))))))))))) -> 声の大きさ [Voice] | P4: =IF(score!B4=30,category!C1,IF(score!B4=29,category!C2,IF(score!B4=28,category!C3,IF(score!B4=27,category!C4,IF(score!B4=26,category!C5,IF(score!B4=25,category!C6,IF(score!B4=24,category!C7,IF(score!B4=23,category!C8,IF(score!B4=22,category!C9,IF(score!B4=21,category!C10,IF(score!B4=20,category!C11,IF(score!B4=19,category!C12,IF(score!B4=18,category!C13,IF(score!B4=17,category!C14,IF(score!B4=16,category!C15,IF(score!B4=15,category!C16,IF(score!B4=14,category!C17,IF(score!B4=13,category!C18,IF(score!B4=12,category!C19,IF(score!B4=11,category!C20,IF(score!B4=10,category!C21,IF(score!B4=9,category!C22,IF(score!B4=8,category!C23,IF(score!B4=7,category!C24,IF(score!B4=6,category!C25,IF(score!B4=5,category!C26,IF(score!B4=4,category!C27,IF(score!B4=3,category!C28,IF(score!B4=2,category!C29,IF(score!B4=1,category!B30,"")))))))))))))))))))))))))))))) -> すらすら言える [Fluency]
K6: ➀ | L6: ➁ | M6: ➂ | N6: ➃ | O6: ➄ | P6: ➀ | Q6: ➁ | R6: ➂ | S6: ➃ | T6: ➄
K11: =IF(score!B4=30,category!D1,IF(score!B4=29,category!D2,IF(score!B4=28,category!D3,IF(score!B4=27,category!D4,IF(score!B4=26,category!D5,IF(score!B4=25,category!D6,IF(score!B4=24,category!D7,IF(score!B4=23,category!D8,IF(score!B4=22,category!D9,IF(score!B4=21,category!D10,IF(score!B4=20,category!D11,IF(score!B4=19,category!D12,IF(score!B4=18,category!D13,IF(score!B4=17,category!D14,IF(score!B4=16,category!D15,IF(score!B4=15,category!D16,IF(score!B4=14,category!D17,IF(score!B4=13,category!D18,IF(score!B4=12,category!D19,IF(score!B4=11,category!D20,IF(score!B4=10,category!D21,IF(score!B4=9,category!D22,IF(score!B4=8,category!D23,IF(score!B4=7,category!D24,IF(score!B4=6,category!D25,IF(score!B4=5,category!D26,IF(score!B4=4,category!D27,IF(score!B4=3,category!D28,IF(score!B4=2,category!D29,IF(score!B4=1,category!B30,"")))))))))))))))))))))))))))))) -> 発音 [Pronunciation] | P11: =IF(score!B4=30,category!E1,IF(score!B4=29,category!E2,IF(score!B4=28,category!E3,IF(score!B4=27,category!E4,IF(score!B4=26,category!E5,IF(score!B4=25,category!E6,IF(score!B4=24,category!E7,IF(score!B4=23,category!E8,IF(score!B4=22,category!E9,IF(score!B4=21,category!E10,IF(score!B4=20,category!E11,IF(score!B4=19,category!E12,IF(score!B4=18,category!E13,IF(score!B4=17,category!E14,IF(score!B4=16,category!E15,IF(score!B4=15,category!E16,IF(score!B4=14,category!E17,IF(score!B4=13,category!E18,IF(score!B4=12,category!E19,IF(score!B4=11,category!E20,IF(score!B4=10,category!E21,IF(score!B4=9,category!E22,IF(score!B4=8,category!E23,IF(score!B4=7,category!E24,IF(score!B4=6,category!E25,IF(score!B4=5,category!E26,IF(score!B4=4,category!E27,IF(score!B4=3,category!E28,IF(score!B4=2,category!E29,IF(score!B4=1,category!B30,"")))))))))))))))))))))))))))))) -> 暗記 [Memorization]
K13: ➀ | L13: ➁ | M13: ➂ | N13: ➃ | O13: ➄ | P13: ➀ | Q13: ➁ | R13: ➂ | S13: ➃ | T13: ➄
K18: =IF(score!B4=30,category!F1,IF(score!B4=29,category!F2,IF(score!B4=28,category!F3,IF(score!B4=27,category!F4,IF(score!B4=26,category!F5,IF(score!B4=25,category!F6,IF(score!B4=24,category!F7,IF(score!B4=23,category!F8,IF(score!B4=22,category!F9,IF(score!B4=21,category!F10,IF(score!B4=20,category!F11,IF(score!B4=19,category!F12,IF(score!B4=18,category!F13,IF(score!B4=17,category!F14,IF(score!B4=16,category!F15,IF(score!B4=15,category!F16,IF(score!B4=14,category!F17,IF(score!B4=13,category!F18,IF(score!B4=12,category!F19,IF(score!B4=11,category!F20,IF(score!B4=10,category!F21,IF(score!B4=9,category!F22,IF(score!B4=8,category!F23,IF(score!B4=7,category!F24,IF(score!B4=6,category!F25,IF(score!B4=5,category!F26,IF(score!B4=4,category!F27,IF(score!B4=3,category!F28,IF(score!B4=2,category!F29,IF(score!B4=1,category!B30,"")))))))))))))))))))))))))))))) -> 内容 [Content] | P18: =IF(score!B4=30,category!G1,IF(score!B4=29,category!G2,IF(score!B4=28,category!G3,IF(score!B4=27,category!G4,IF(score!B4=26,category!G5,IF(score!B4=25,category!G6,IF(score!B4=24,category!G7,IF(score!B4=23,category!G8,IF(score!B4=22,category!G9,IF(score!B4=21,category!G10,IF(score!B4=20,category!G11,IF(score!B4=19,category!G12,IF(score!B4=18,category!G13,IF(score!B4=17,category!G14,IF(score!B4=16,category!G15,IF(score!B4=15,category!G16,IF(score!B4=14,category!G17,IF(score!B4=13,category!G18,IF(score!B4=12,category!G19,IF(score!B4=11,category!G20,IF(score!B4=10,category!G21,IF(score!B4=9,category!G22,IF(score!B4=8,category!G23,IF(score!B4=7,category!G24,IF(score!B4=6,category!G25,IF(score!B4=5,category!G26,IF(score!B4=4,category!G27,IF(score!B4=3,category!G28,IF(score!B4=2,category!G29,IF(score!B4=1,category!B30,"")))))))))))))))))))))))))))))) -> ジェスチャー [Gesture]
K20: ➀ | L20: ➁ | M20: ➂ | N20: ➃ | O20: ➄ | P20: ➀ | Q20: ➁ | R20: ➂ | S20: ➃ | T20: ➄
B21: =IF(score!B4=30,comment!B7&" "&comment!B13&" "&comment!B19&" "&comment!B25&" "&comment!B31&" "&comment!B37&" "&comment!B43&" "&comment!B49,IF(score!B4=29,comment!C7&" "&comment!C13&" "&comment!C19&" "&comment!C25&" "&comment!C31&" "&comment!C37&" "&comment!C43&" "&comment!C49,IF(score!B4=28,comment!D7&" "&comment!D13&" "&comment!D19&" "&comment!D25&" "&comment!D31&" "&comment!D37&" "&comment!D43&" "&comment!D49,IF(score!B4=27,comment!E7&" "&comment!E13&" "&comment!E19&" "&comment!E25&" "&comment!E31&" "&comment!E37&" "&comment!E43&" "&comment!E49,IF(score!B4=26,comment!F7&" "&comment!F13&" "&comment!F19&" "&comment!F25&" "&comment!F31&" "&comment!F37&" "&comment!F43&" "&comment!F49,IF(score!B4=25,comment!G7&" "&comment!G13&" "&comment!G19&" "&comment!G25&" "&comment!G31&" "&comment!G37&" "&comment!G43&" "&comment!G49,IF(score!B4=24,comment!H7&" "&comment!H13&" "&comment!H19&" "&comment!H25&" "&comment!H31&" "&comment!H37&" "&comment!H43&" "&comment!H49,IF(score!B4=23,comment!I7&" "&comment!I13&" "&comment!I19&" "&comment!I25&" "&comment!I31&" "&comment!I37&" "&comment!I43&" "&comment!I49,IF(score!B4=22,comment!J7&" "&comment!J13&" "&comment!J19&" "&comment!J25&" "&comment!J31&" "&comment!J37&" "&comment!J43&" "&comment!J49,IF(score!B4=21,comment!K7&" "&comment!K13&" "&comment!K19&" "&comment!K25&" "&comment!K31&" "&comment!K37&" "&comment!K43&" "&comment!K49,IF(score!B4=20,comment!L7&" "&comment!L13&" "&comment!L19&" "&comment!L25&" "&comment!L31&" "&comment!L37&" "&comment!L43&" "&comment!L49,IF(score!B4=19,comment!M7&" "&comment!M13&" "&comment!M19&" "&comment!M25&" "&comment!M31&" "&comment!M37&" "&comment!M43&" "&comment!M49,IF(score!B4=18,comment!N7&" "&comment!N13&" "&comment!N19&" "&comment!N25&" "&comment!N31&" "&comment!N37&" "&comment!N43&" "&comment!N49,IF(score!B4=17,comment!O7&" "&comment!O13&" "&comment!O19&" "&comment!O25&" "&comment!O31&" "&comment!O37&" "&comment!O43&" "&comment!O49,IF(score!B4=16,comment!P7&" "&comment!P13&" "&comment!P19&" "&comment!P25&" "&comment!P31&" "&comment!P37&" "&comment!P43&" "&comment!P49,IF(score!B4=15,comment!Q7&" "&comment!Q13&" "&comment!Q19&" "&comment!Q25&" "&comment!Q31&" "&comment!Q37&" "&comment!Q43&" "&comment!Q49,IF(score!B4=14,comment!R7&" "&comment!R13&" "&comment!R19&" "&comment!R25&" "&comment!R31&" "&comment!R37&" "&comment!R43&" "&comment!R49,IF(score!B4=13,comment!S7&" "&comment!S13&" "&comment!S19&" "&comment!S25&" "&comment!S31&" "&comment!S37&" "&comment!S43&" "&comment!S49,IF(score!B4=12,comment!T7&" "&comment!T13&" "&comment!T19&" "&comment!T25&" "&comment!T31&" "&comment!T37&" "&comment!T43&" "&comment!T49,IF(score!B4=11,comment!U7&" "&comment!U13&" "&comment!U19&" "&comment!U25&" "&comment!U31&" "&comment!U37&" "&comment!U43&" "&comment!U49,IF(score!B4=10,comment!V7&" "&comment!V13&" "&comment!V19&" "&comment!V25&" "&comment!V31&" "&comment!V37&" "&comment!V43&" "&comment!V49,IF(score!B4=9,comment!W7&" "&comment!W13&" "&comment!W19&" "&comment!W25&" "&comment!W31&" "&comment!W37&" "&comment!W43&" "&comment!W49,IF(score!B4=8,comment!X7&" "&comment!X13&" "&comment!X19&" "&comment!X25&" "&comment!X31&" "&comment!X37&" "&comment!X43&" "&comment!X49,IF(score!B4=7,comment!Y7&" "&comment!Y13&" "&comment!Y19&" "&comment!Y25&" "&comment!Y31&" "&comment!Y37&" "&comment!Y43&" "&comment!Y49,IF(score!B4=6,comment!Z7&" "&comment!Z13&" "&comment!Z19&" "&comment!Z25&" "&comment!Z31&" "&comment!Z37&" "&comment!Z43&" "&comment!Z49,IF(score!B4=5,comment!AA7&" "&comment!AA13&" "&comment!AA19&" "&comment!AA25&" "&comment!AA31&" "&comment!AA37&" "&comment!AA43&" "&comment!AA49,IF(score!B4=4,comment!AB7&" "&comment!AB13&" "&comment!AB19&" "&comment!AB25&" "&comment!AB31&" "&comment!AB37&" "&comment!AB43&" "&comment!AB49,IF(score!B4=3,comment!AC7&" "&comment!AC13&" "&comment!AC19&" "&comment!AC25&" "&comment!AC31&" "&comment!AC37&" "&comment!AC43&" "&comment!AC49,IF(score!B4=2,comment!AD7&" "&comment!AD13&" "&comment!AD19&" "&comment!AD25&" "&comment!AD31&" "&comment!AD37&" "&comment!AD43&" "&comment!AD49,IF(score!B4=1,comment!AE7&" "&comment!AE13&" "&comment!AE19&" "&comment!AE25&" "&comment!AE31&" "&comment!AE37&" "&comment!AE43&" "&comment!AE49," ")))))))))))))))))))))))))))))) -> 18級では、ものがどこにあるか場所を説明する表現・自分の習慣について学習をしました。スピーチでは、準備や練習もがんばり、一部原稿を見ないで発表をすることができました！次回は原稿をすべて覚えてスピーチに挑戦してみよう♪ Good☆
K25: =IF(score!B4=30,category!H1,IF(score!B4=29,category!H2,IF(score!B4=28,category!H3,IF(score!B4=27,category!H4,IF(score!B4=26,category!H5,IF(score!B4=25,category!H6,IF(score!B4=24,category!H7,IF(score!B4=23,category!H8,IF(score!B4=22,category!H9,IF(score!B4=21,category!H10,IF(score!B4=20,category!H11,IF(score!B4=19,category!H12,IF(score!B4=18,category!H13,IF(score!B4=17,category!H14,IF(score!B4=16,category!H15,IF(score!B4=15,category!H16,IF(score!B4=14,category!H17,IF(score!B4=13,category!H18,IF(score!B4=12,category!H19,IF(score!B4=11,category!H20,IF(score!B4=10,category!H21,IF(score!B4=9,category!H22,IF(score!B4=8,category!H23,IF(score!B4=7,category!H24,IF(score!B4=6,category!H25,IF(score!B4=5,category!H26,IF(score!B4=4,category!H27,IF(score!B4=3,category!H28,IF(score!B4=2,category!H29,IF(score!B4=1,category!B30,"")))))))))))))))))))))))))))))) -> 顔の表情や目線 [Facial Expressions, Eyes] | P25: =IF(score!B4=30,category!I1,IF(score!B4=29,category!I2,IF(score!B4=28,category!I3,IF(score!B4=27,category!I4,IF(score!B4=26,category!I5,IF(score!B4=25,category!I6,IF(score!B4=24,category!I7,IF(score!B4=23,category!I8,IF(score!B4=22,category!I9,IF(score!B4=21,category!I10,IF(score!B4=20,category!I11,IF(score!B4=19,category!I12,IF(score!B4=18,category!I13,IF(score!B4=17,category!I14,IF(score!B4=16,category!I15,IF(score!B4=15,category!I16,IF(score!B4=14,category!I17,IF(score!B4=13,category!I18,IF(score!B4=12,category!I19,IF(score!B4=11,category!I20,IF(score!B4=10,category!I21,IF(score!B4=9,category!I22,IF(score!B4=8,category!I23,IF(score!B4=7,category!I24,IF(score!B4=6,category!I25,IF(score!B4=5,category!I26,IF(score!B4=4,category!I27,IF(score!B4=3,category!I28,IF(score!B4=2,category!I29,IF(score!B4=1,category!B30,"")))))))))))))))))))))))))))))) -> 態度 [Atittude]
K27: ➀ | L27: ➁ | M27: ➂ | N27: ➃ | O27: ➄ | P27: ➀ | Q27: ➁ | R27: ➂ | S27: ➃ | T27: ➄

Sheet comment
B1: 30 | C1: 29 | D1: 28 | E1: 27 | F1: 26 | G1: 25 | H1: 24 | I1: 23 | J1: 22 | K1: 21 | L1: 20 | M1: 19 | N1: 18 | O1: 17 | P1: 16 | Q1: 15 | R1: 14 | S1: 13 | T1: 12 | U1: 11 | V1: 10 | W1: 9 | X1: 8 | Y1: 7 | Z1: 6 | AA1: 5 | AB1: 4 | AC1: 3 | AD1: 2 | AE1: 1
A2: =score!C2 -> 4 | B2: 30c1 | C2: 29c1 | D2: 28c1 | E2: 27c1 | F2: 26c1 | G2: 25c1 | H2: 残念ながら、緊張してしまったのか先生のあいさつを聞くことができませんでした。 | I2: 23級では、ショッピングで役に立つ表現を学習しました。まだ練習中で英語で"Hello"はできませんでした。 | J2: 22級では、ほしいものや必要なものを英語で言う表現を学習しました。まだ練習中で英語でのあいさつはできませんでした。 | K2: まだ練習中で英語でのあいさつはできませんでした。 | L2: 20級では、「自分の名前・年れい・体の調子・好きなもの・好きではないもの・持っているもの・ほしいもの・暑い日に着るもの・天気」をテーマにスピーチをしました。残念ながら、まだ練習中で発表はできませんでした。次回は発表できるように先生と練習しよう！ | M2: 19級では、自分や家族の紹介（できること・性格など）をしました。まだ練習中で英語でのあいさつはできませんでした。 | N2: 18級では、ものがどこにあるか場所を説明する表現・自分の習慣について学習をしました。スピーチでは、残念ながら、まだ練習中で発表はできませんでした。次回は発表できるように先生と練習しよう！ | O2: まだ練習中で英語でのあいさつはできませんでした。 | P2: 16級では、道案内、将来の夢、家族紹介の学習をしました。テストでは、「誕生日にほしいもの(16級)・年中行事(16級)・家族紹介」にテーマにスピーチをしました。残念ながら、まだ練習中で発表はできませんでした。次回は発表できるように先生と練習しよう！ | Q2: 15級では、世界の国々にある建物や有名なものについて学習しました。まだ練習中であいさつはできませんでした。 | R2: 14級では、「出身・自分の国にあるもの・それがどんなものか・ふだんすること・時々すること・いつもすること」をテーマにスピーチをしました。残念ながら、まだ練習中で発表はできませんでした。次回は発表できるように先生と練習しよう！ | S2: 13級では、病院でお医者さんに症状を英語で伝える表現・三人称単数現在形のS・現在進行形・Be動詞を学習しました。まだ練習中で英語でのあいさつはできませんでした。 | T2: 12級では、過去1週間にしたことをテーマにスピーチをしました。残念ながら、まだ練習中で発表はできませんでした。次回は発表できるように先生と練習しよう！ | U2: 11級では、Why?（なぜ）に対して理由を説明する学習しました。まだ練習中で英語でのあいさつはできませんでした。 | V2: 10級では、「自分の出身地・出身地の有名な事柄・自分が持っているもの・自分が得意な事・自分の日常・家族の職業・家族が得意な事・自分が好きな事とその理由」をテーマにスピーチをしました。残念ながら、まだ練習中で発表はできませんでした。次回は発表できるように先生と練習しよう！ | W2: 9級では不定詞/過去進行形/whenを使った表現、 to+動詞の原形(すること/するための・すべき/するために・~して)とwas/were+動詞ingを学習しました。 テストでは過去のある時点で誰が何をしていたかを説明する英語を使いアリバイゲームをしました。残念ながら、まだ練習中でした。次回はできるように先生と練習しよう！ | X2: 8級では、「家族の性格・家族がふだんすること・ある日の家族との思い出・自分の週末の紹介・週末にする予定・雨天の場合の予定・週末にしなくてもよいこと・週末にしなくてはいけないこと」をテーマにスピーチをしました。残念ながら、まだ練習中で発表はできませんでした。次回は発表できるように先生と練習しよう！ | Y2: 7級では、さまざまな人やものを比べる表現を学習しました。まだ練習中で英語でのあいさつや自己紹介はできませんでした。 | Z2: 6級では、自分がしたいことをテーマにスピーチをしました。残念ながら、まだ練習中で発表はできませんでした。次回は発表できるように先生と練習しよう！ | AA2: 5級では、現在完了形の表現を学習しました。まだ練習中で英語でのあいさつや自己紹介はできませんでした。 | AB2: 4級では、「自分についての紹介・生まれ・今住んでいるところ・することが好きなこと・長い間していること・持っている特別なもの・行ったことがある場所・その場所の説明・終わりのあいさつ」をテーマにスピーチをしました。残念ながら、まだ練習中で発表はできませんでした。次回は発表できるように先生と練習しよう！ | AC2: 3級では、さまざまな表現(仮定法・不可疑問・間接疑問など)を学習しました。まだ練習中で英語でのあいさつや自己紹介はできませんでした。 | AD2: 2級では、9級から3級までに学習した文法が入った長めの自己紹介をテーマにスピーチをしました（生まれ・育ち・2つのものを比べてどちらが好きかとその理由・将来の夢としたいこと・どんな人になりたいか・もしお金持ちだったらしてみたいこと）。残念ながら、まだ練習中で発表はできませんでした。次回は発表できるように先生と練習しよう！ | AE2: 1c1
B3: 30c2 | C3: 29c2 | D3: 28c2 | E3: 27c2 | F3: 26c2 | G3: 25c2 | H3: まだ練習中で英語で"Hello"はできませんでした。 | I3: 23級では、ショッピングで役に立つ表現を学習しました。先生の後に続いてまねをして"Hello"ができました。 | J3: 22級では、ほしいものや必要なものを英語で言う表現を学習しました。先生の後に続いてまねをして英語のあいさつができました。 | K3: 先生の後に続いてまねをして英語のあいさつができました。 | L3: 20級では、「自分の名前・年れい・体の調子・好きなもの・好きではないもの・持っているもの・ほしいもの・暑い日に着るもの・天気」をテーマにスピーチをしました。スピーチの発表はできませんでしたが、先生の後に続いてスピーチ原稿を読むことができました。次回は発表できるように先生と練習しよう！ | M3: 19級では、自分や家族の紹介（できること・性格など）をしました。先生の後に続いてまねをして英語のあいさつができました。 | N3: 18級では、ものがどこにあるか場所を説明する表現・自分の習慣について学習をしました。スピーチでは、発表はできませんでしたが、先生の後に続いてスピーチ原稿を読むことができました。次回は発表できるように先生と練習しよう！ | O3: 先生の後に続いてまねをして英語のあいさつができました。 | P3: 16級では、道案内、将来の夢、家族紹介の学習をしました。テストでは、「誕生日にほしいもの(16級)・年中行事(16級)・家族紹介」にテーマにスピーチをしました。スピーチの発表はできませんでしたが、先生の後に続いてスピーチ原稿を読むことができました。次回は発表できるように先生と練習しよう！ | Q3: 15級では、世界の国々にある建物や有名なものについて学習しました。先生の後に続いてまねをして英語のあいさつができました。 | R3: 14級では、「出身・自分の国にあるもの・それがどんなものか・ふだんすること・時々すること・いつもすること」をテーマにスピーチをしました。スピーチの発表はできませんでしたが、先生の後に続いてスピーチ原稿を読むことができました。次回は発表できるように先生と練習しよう！ | S3: 13級では、病院でお医者さんに症状を英語で伝える表現・三人称単数現在形のS・現在進行形・Be動詞を学習しました。先生の後に続いてまねをして英語のあいさつができました。 | T3: 12級では、過去1週間にしたことをテーマにスピーチをしました。スピーチの発表はできませんでしたが、先生の後に続いてスピーチ原稿を読むことができました。次回は発表できるように先生と練習しよう！ | U3: 11級では、Why?（なぜ）に対して理由を説明する学習しました。先生の後に続いてまねをして英語のあいさつができました。 | V3: 10級では、「自分の出身地・出身地の有名な事柄・自分が持っているもの・自分が得意な事・自分の日常・家族の職業・家族が得意な事・自分が好きな事とその理由」をテーマにスピーチをしました。スピーチの発表はできませんでしたが、先生の後に続いてスピーチ原稿を読むことができました。次回は発表できるように先生と練習しよう！ | W3: 9級では不定詞/過去進行形/whenを使った表現、 to+動詞の原形(すること/するための・すべき/するために・~して)とwas/were+動詞ingを学習しました。 テストでは過去のある時点で誰が何をしていたかを説明する英語を使いアリバイゲームをしました。自力ではできませんでしたが、先生の後に続いて自分の説明をすることができました。次回は自力で発表できるように先生と練習しよう！ | X3: 8級では、「家族の性格・家族がふだんすること・ある日の家族との思い出・自分の週末の紹介・週末にする予定・雨天の場合の予定・週末にしなくてもよいこと・週末にしなくてはいけないこと」をテーマにスピーチをしました。スピーチの発表はできませんでしたが、先生の後に続いてスピーチ原稿を読むことができました。次回は発表できるように先生と練習しよう！ | Y3: 7級では、さまざまな人やものを比べる表現を学習しました。先生の後に続いてまねをして英語でのあいさつや自己紹介ができました。 | Z3: 6級では、自分がしたいことをテーマにスピーチをしました。スピーチの発表はできませんでしたが、先生の後に続いてスピーチ原稿を読むことができました。次回は発表できるように先生と練習しよう！ | AA3: 5級では、現在完了形の表現を学習しました。先生の後に続いてまねをして英語でのあいさつや自己紹介ができました。 | AB3: 4級では、「自分についての紹介・生まれ・今住んでいるところ・することが好きなこと・長い間していること・持っている特別なもの・行ったことがある場所・その場所の説明・終わりのあいさつ」をテーマにスピーチをしました。スピーチの発表はできませんでしたが、先生の後に続いてスピーチ原稿を読むことができました。次回は発表できるように先生と練習しよう！ | AC3: 3級では、さまざまな表現(仮定法・不可疑問・間接疑問など)を学習しました。先生の後に続いてまねをして英語でのあいさつや自己紹介ができました。 | AD3: 2級では、9級から3級までに学習した文法が入った長めの自己紹介をテーマにスピーチをしました（生まれ・育ち・2つのものを比べてどちらが好きかとその理由・将来の夢としたいこと・どんな人になりたいか・もしお金持ちだったらしてみたいこと）。スピーチの発表はできませんでしたが、先生の後に続いてスピーチ原稿を読むことができました。次回は発表できるように先生と練習しよう！ | AE3: 1c2
B4: 30c3 | C4: 29c3 | D4: 28c3 | E4: 27c3 | F4: 26c3 | G4: 25c3 | H4: 先生の後に続いてまねをして"Hello"ができました。 | I4: 23級では、ショッピングで役に立つ表現を学習しました。"What's your name?"に答えることができました！ | J4: 22級では、ほしいものや必要なものを英語で言う表現を学習しました。自分の名前を英語で言えました！ | K4: 自分の名前を英語で言えました！ | L4: 20級では、「自分の名前・年れい・体の調子・好きなもの・好きではないもの・持っているもの・ほしいもの・暑い日に着るもの・天気」をテーマにスピーチをしました。先生のヒントもありながら、スピーチ原稿を自分で読むことができました。頑張りましたね！次回は少し原稿を覚えてスピーチに挑戦してみよう☆ | M4: 19級では、自分や家族の紹介（できること・性格など）をしました。自分の名前を英語で言えました！ | N4: 18級では、ものがどこにあるか場所を説明する表現・自分の習慣について学習をしました。スピーチでは、先生のヒントもありながら、スピーチ原稿を自分で読むことができました。頑張りましたね！次回は少し原稿を覚えてスピーチに挑戦してみよう☆ | O4: 自分の名前を英語で言えました！ | P4: 16級では、道案内、将来の夢、家族紹介の学習をしました。テストでは、「誕生日にほしいもの(16級)・年中行事(16級)・家族紹介」にテーマにスピーチをしました。先生のヒントもありながら、スピーチ原稿を自分で読むことができました。頑張りましたね！次回は少し原稿を覚えてスピーチに挑戦してみよう☆ | Q4: 15級では、世界の国々にある建物や有名なものについて学習しました。自分の名前を英語で言えました！ | R4: 14級では、「出身・自分の国にあるもの・それがどんなものか・ふだんすること・時々すること・いつもすること」をテーマにスピーチをしました。先生のヒントもありながら、スピーチ原稿を自分で読むことができました。頑張りましたね！次回は少し原稿を覚えてスピーチに挑戦してみよう☆ | S4: 13級では、病院でお医者さんに症状を英語で伝える表現・三人称単数現在形のS・現在進行形・Be動詞を学習しました。自分の名前を英語で言えました！ | T4: 12級では、過去1週間にしたことをテーマにスピーチをしました。先生のヒントもありながら、スピーチ原稿を自分で読むことができました。頑張りましたね！次回は少し原稿を覚えてスピーチに挑戦してみよう☆ | U4: 11級では、Why?（なぜ）に対して理由を説明する学習しました。自分の名前・年れいを英語で言えました！ | V4: 10級では、「自分の出身地・出身地の有名な事柄・自分が持っているもの・自分が得意な事・自分の日常・家族の職業・家族が得意な事・自分が好きな事とその理由」をテーマにスピーチをしました。先生のヒントもありながら、スピーチ原稿を自分で読むことができました。頑張りましたね！次回は少し原稿を覚えてスピーチに挑戦してみよう☆ | W4: 9級では不定詞/過去進行形/whenを使った表現、 to+動詞の原形(すること/するための・すべき/するために・~して)とwas/were+動詞ingを学習しました。 テストでは過去のある時点で誰が何をしていたかを説明する英語を使いアリバイゲームをしました。先生のヒントもありながら、自分の説明をする事ができました。頑張りましたね！次回はヒント無しで発言することに挑戦してみよう☆ | X4: 8級では、「家族の性格・家族がふだんすること・ある日の家族との思い出・自分の週末の紹介・週末にする予定・雨天の場合の予定・週末にしなくてもよいこと・週末にしなくてはいけないこと」をテーマにスピーチをしました。先生のヒントもありながら、スピーチ原稿を自分で読むことができました。頑張りましたね！次回は少し原稿を覚えてスピーチに挑戦してみよう☆ | Y4: 7級では、さまざまな人やものを比べる表現を学習しました。自分の名前を英語で言えました！ | Z4: 6級では、自分がしたいことをテーマにスピーチをしました。先生のヒントもありながら、スピーチ原稿を自分で読むことができました。頑張りましたね！次回は少し原稿を覚えてスピーチに挑戦してみよう☆ | AA4: 5級では、現在完了形の表現を学習しました。自分の名前・年れいを英語で言えました！ | AB4: 4級では、「自分についての紹介・生まれ・今住んでいるところ・することが好きなこと・長い間していること・持っている特別なもの・行ったことがある場所・その場所の説明・終わりのあいさつ」をテーマにスピーチをしました。先生のヒントもありながら、スピーチ原稿を自分で読むことができました。頑張りましたね！次回は少し原稿を覚えてスピーチに挑戦してみよう☆ | AC4: 3級では、さまざまな表現(仮定法・不可疑問・間接疑問など)を学習しました。自分の名前・年齢・体の調子・天気を英語で言えました！ | AD4: 2級では、9級から3級までに学習した文法が入った長めの自己紹介をテーマにスピーチをしました（生まれ・育ち・2つのものを比べてどちらが好きかとその理由・将来の夢としたいこと・どんな人になりたいか・もしお金持ちだったらしてみたいこと）。先生のヒントもありながら、スピーチ原稿を自分で読むことができました。頑張りましたね！次回は少し原稿を覚えてスピーチに挑戦してみよう☆ | AE4: 1c3
B5: 30c4 | C5: 29c4 | D5: 28c4 | E5: 27c4 | F5: 26c4 | G5: 25c4 | H5: "Hello"を英語で言えました！ | I5: 23級では、ショッピングで役に立つ表現を学習しました。自分の名前、年れいを英語で言えました！ | J5: 22級では、ほしいものや必要なものを英語で言う表現を学習しました。自分の名前・年れいを英語で言えました！ | K5: 自分の名前・年れいを英語で言えました！ | L5: 20級では、「自分の名前・年れい・体の調子・好きなもの・好きではないもの・持っているもの・ほしいもの・暑い日に着るもの・天気」をテーマにスピーチをしました。準備や練習もがんばり、一部原稿を見ないで発表をすることができました！次回は原稿をすべて覚えてスピーチに挑戦してみよう♪ Good☆ | M5: 19級では、自分や家族の紹介（できること・性格など）をしました。自分の名前・年れいを英語で言えました！ | N5: 18級では、ものがどこにあるか場所を説明する表現・自分の習慣について学習をしました。スピーチでは、準備や練習もがんばり、一部原稿を見ないで発表をすることができました！次回は原稿をすべて覚えてスピーチに挑戦してみよう♪ Good☆ | O5: 自分の名前・年れいを英語で言えました！ | P5: 16級では、道案内、将来の夢、家族紹介の学習をしました。テストでは、「誕生日にほしいもの(16級)・年中行事(16級)・家族紹介」にテーマにスピーチをしました。準備や練習もがんばり、一部原稿を見ないで発表をすることができました！次回は原稿をすべて覚えてスピーチに挑戦してみよう♪ Good☆ | Q5: 15級では、世界の国々にある建物や有名なものについて学習しました。自分の名前・年れいを英語で言えました！ | R5: 14級では、「出身・自分の国にあるもの・それがどんなものか・ふだんすること・時々すること・いつもすること」をテーマにスピーチをしました。準備や練習もがんばり、一部原稿を見ないで発表をすることができました！次回は原稿をすべて覚えてスピーチに挑戦してみよう♪ Good☆ | S5: 13級では、病院でお医者さんに症状を英語で伝える表現・三人称単数現在形のS・現在進行形・Be動詞を学習しました。自分の名前・年れいを英語で言えました！ | T5: 12級では、過去1週間にしたことをテーマにスピーチをしました。準備や練習もがんばり、一部原稿を見ないで発表をすることができました！次回は原稿をすべて覚えてスピーチに挑戦してみよう♪ Good☆ | U5: 11級では、Why?（なぜ）に対して理由を説明する学習しました。自分の名前・年れい・体の調子を英語で言えました！ | V5: 10級では、「自分の出身地・出身地の有名な事柄・自分が持っているもの・自分が得意な事・自分の日常・家族の職業・家族が得意な事・自分が好きな事とその理由」をテーマにスピーチをしました。準備や練習もがんばり、一部原稿を見ないで発表をすることができました！次回は原稿をすべて覚えてスピーチに挑戦してみよう♪ Good☆ | W5: 9級では不定詞/過去進行形/whenを使った表現、 to+動詞の原形(すること/するための・すべき/するために・~して)とwas/were+動詞ingを学習しました。 テストでは過去のある時点で誰が何をしていたかを説明する英語を使いアリバイゲームをしました。準備や練習もがんばり、一部自分の言葉で説明することができました！次回は先生の急な質問にも全て英語で答えることに挑戦してみよう♪ Good☆ | X5: 8級では、「家族の性格・家族がふだんすること・ある日の家族との思い出・自分の週末の紹介・週末にする予定・雨天の場合の予定・週末にしなくてもよいこと・週末にしなくてはいけないこと」をテーマにスピーチをしました。準備や練習もがんばり、一部原稿を見ないで発表をすることができました！次回は原稿をすべて覚えてスピーチに挑戦してみよう♪ Good☆ | Y5: 7級では、さまざまな人やものを比べる表現を学習しました。自分の名前・年れいを英語で言えました！ | Z5: 6級では、自分がしたいことをテーマにスピーチをしました。準備や練習もがんばり、一部原稿を見ないで発表をすることができました！次回は原稿をすべて覚えてスピーチに挑戦してみよう♪ Good☆ | AA5: 5級では、現在完了形の表現を学習しました。自分の名前・年れい・体の調子を英語で言えました！ | AB5: 4級では、「自分についての紹介・生まれ・今住んでいるところ・することが好きなこと・長い間していること・持っている特別なもの・行ったことがある場所・その場所の説明・終わりのあいさつ」をテーマにスピーチをしました。準備や練習もがんばり、一部原稿を見ないで発表をすることができました！次回は原稿をすべて覚えてスピーチに挑戦してみよう♪ Good☆ | AC5: 3級では、さまざまな表現(仮定法・不可疑問・間接疑問など)を学習しました。自分の名前・年齢・体の調子・天気・誕生日を英語で言えました！ | AD5: 2級では、9級から3級までに学習した文法が入った長めの自己紹介をテーマにスピーチをしました（生まれ・育ち・2つのものを比べてどちらが好きかとその理由・将来の夢としたいこと・どんな人になりたいか・もしお金持ちだったらしてみたいこと）。準備や練習もがんばり、一部原稿を見ないで発表をすることができました！次回は原稿をすべて覚えてスピーチに挑戦してみよう♪ Good☆ | AE5: 1c4
B6: 30c5 | C6: 29c5 | D6: 28c5 | E6: 27c5 | F6: 26c5 | G6: 25c5 | H6: 英語であいさつはばっちり！Great☆ | I6: 23級では、ショッピングで役に立つ表現を学習しました。自分の名前、年れい、体の調子を英語で言えました！Great☆ | J6: 22級では、ほしいものや必要なものを英語で言う表現を学習しました。英語での自己紹介はばっちり！Great☆ | K6: 英語での自己紹介はばっちり！Great☆ | L6: 20級では、「自分の名前・年れい・体の調子・好きなもの・好きではないもの・持っているもの・ほしいもの・暑い日に着るもの・天気」をテーマにスピーチをしました。準備や練習をとてもしっかりとして、スピーチを見ないで発表することができました！発表を聞いている人のことも考えて、目線やジェスチャーなども意識することができました。Awesome☆ | M6: 19級では、自分や家族の紹介（できること・性格など）をしました。英語での自己紹介はばっちり！Great☆ | N6: 18級では、ものがどこにあるか場所を説明する表現・自分の習慣について学習をしました。スピーチでは、準備や練習をとてもしっかりとして、スピーチを見ないで発表することができました！発表を聞いている人のことも考えて、目線やジェスチャーなども意識することができました。Awesome☆ | O6: 英語での自己紹介はばっちり！Great☆ | P6: 16級では、道案内、将来の夢、家族紹介の学習をしました。テストでは、「誕生日にほしいもの(16級)・年中行事(16級)・家族紹介」にテーマにスピーチをしました。準備や練習をとてもしっかりとして、スピーチを見ないで発表することができました！発表を聞いている人のことも考えて、目線やジェスチャーなども意識することができました。Awesome☆ | Q6: 15級では、世界の国々にある建物や有名なものについて学習しました。英語での自己紹介はばっちり！Great☆ | R6: 14級では、「出身・自分の国にあるもの・それがどんなものか・ふだんすること・時々すること・いつもすること」をテーマにスピーチをしました。準備や練習をとてもしっかりとして、スピーチを見ないで発表することができました！発表を聞いている人のことも考えて、目線やジェスチャーなども意識することができました。Awesome☆ | S6: 13級では、病院でお医者さんに症状を英語で伝える表現・三人称単数現在形のS・現在進行形・Be動詞を学習しました。英語での自己紹介はばっちり！Great☆ | T6: 12級では、過去1週間にしたことをテーマにスピーチをしました。準備や練習をとてもしっかりとして、スピーチを見ないで発表することができました！発表を聞いている人のことも考えて、目線やジェスチャーなども意識することができました。Awesome☆ | U6: 11級では、Why?（なぜ）に対して理由を説明する学習しました。英語での自己紹介はばっちり！Great☆ | V6: 10級では、「自分の出身地・出身地の有名な事柄・自分が持っているもの・自分が得意な事・自分の日常・家族の職業・家族が得意な事・自分が好きな事とその理由」をテーマにスピーチをしました。準備や練習をとてもしっかりとして、スピーチを見ないで発表することができました！発表を聞いている人のことも考えて、目線やジェスチャーなども意識することができました。Awesome☆ | W6: 9級では不定詞/過去進行形/whenを使った表現、 to+動詞の原形(すること/するための・すべき/するために・~して)とwas/were+動詞ingを学習しました。 テストでは過去のある時点で誰が何をしていたかを説明する英語を使いアリバイゲームをしました。準備や練習をとてもしっかりとして、用意した文章を使わず自分の言葉で説明することができました！説明を聞いている人のことも考えて、目線やジェスチャーなども意識することができました。Awesome☆ | X6: 8級では、「家族の性格・家族がふだんすること・ある日の家族との思い出・自分の週末の紹介・週末にする予定・雨天の場合の予定・週末にしなくてもよいこと・週末にしなくてはいけないこと」をテーマにスピーチをしました。準備や練習をとてもしっかりとして、スピーチを見ないで発表することができました！発表を聞いている人のことも考えて、目線やジェスチャーなども意識することができました。Awesome☆ | Y6: 7級では、さまざまな人やものを比べる表現を学習しました。英語での自己紹介はばっちり！Great☆ | Z6: 6級では、自分がしたいことをテーマにスピーチをしました。準備や練習をとてもしっかりとして、スピーチを見ないで発表することができました！発表を聞いている人のことも考えて、目線やジェスチャーなども意識することができました。Awesome☆ | AA6: 5級では、現在完了形の表現を学習しました。英語での自己紹介はばっちり！Great☆ | AB6: 4級では、「自分についての紹介・生まれ・今住んでいるところ・することが好きなこと・長い間していること・持っている特別なもの・行ったことがある場所・その場所の説明・終わりのあいさつ」をテーマにスピーチをしました。準備や練習をとてもしっかりとして、スピーチを見ないで発表することができました！発表を聞いている人のことも考えて、目線やジェスチャーなども意識することができました。Awesome☆ | AC6: 3級では、さまざまな表現(仮定法・不可疑問・間接疑問など)を学習しました。英語での自己紹介はカンペキ！Great☆ | AD6: 2級では、9級から3級までに学習した文法が入った長めの自己紹介をテーマにスピーチをしました（生まれ・育ち・2つのものを比べてどちらが好きかとその理由・将来の夢としたいこと・どんな人になりたいか・もしお金持ちだったらしてみたいこと）。準備や練習をとてもしっかりとして、スピーチを見ないで発表することができました！発表を聞いている人のことも考えて、目線やジェスチャーなども意識することができました。Awesome☆ | AE6: 1c5
B7: =IF($A$2=1,B2,IF($A$2=2,B3,IF($A$2=3,B4,IF($A$2=4,B5,IF($A$2=5,B6,"-"))))) -> 30c4 | C7: =IF($A$2=1,C2,IF($A$2=2,C3,IF($A$2=3,C4,IF($A$2=4,C5,IF($A$2=5,C6,"-"))))) -> 29c4 | D7: =IF($A$2=1,D2,IF($A$2=2,D3,IF($A$2=3,D4,IF($A$2=4,D5,IF($A$2=5,D6,"-"))))) -> 28c4 | E7: =IF($A$2=1,E2,IF($A$2=2,E3,IF($A$2=3,E4,IF($A$2=4,E5,IF($A$2=5,E6,"-"))))) -> 27c4 | F7: =IF($A$2=1,F2,IF($A$2=2,F3,IF($A$2=3,F4,IF($A$2=4,F5,IF($A$2=5,F6,"-"))))) -> 26c4 | G7: =IF($A$2=1,G2,IF($A$2=2,G3,IF($A$2=3,G4,IF($A$2=4,G5,IF($A$2=5,G6,"-"))))) -> 25c4 | H7: =IF($A$2=1,H2,IF($A$2=2,H3,IF($A$2=3,H4,IF($A$2=4,H5,IF($A$2=5,H6,"-"))))) -> "Hello"を英語で言えました！ | I7: =IF($A$2=1,I2,IF($A$2=2,I3,IF($A$2=3,I4,IF($A$2=4,I5,IF($A$2=5,I6,"-"))))) -> 23級では、ショッピングで役に立つ表現を学習しました。自分の名前、年れいを英語で言えました！ | ... AE7: =IF($A$2=1,AE2,IF($A$2=2,AE3,IF($A$2=3,AE4,IF($A$2=4,AE5,IF($A$2=5,AE6,"-"))))) -> 1c4
A8: =score!D2 -> 4 | B8: 30c1 | C8: 29c1 | D8: 28c1 | E8: 27c1 | F8: 26c1 | G8: 25c1 | H8: 残念ながら、緊張してしまったのか先生の"What's your name?"を聞くことができませんでした。 | I8: まだ練習中でお花の単語はわかりませんでした。 | J8: まだ練習中で食べ物の単語はわかりませんでした。 | K8: まだ練習中で曜日の単語はわかりませんでした。 | M8: まだ練習中で楽器の単語はわかりませんでした。 | O8: まだ練習中で体のパーツの単語はわかりませんでした。 | Q8: まだ練習中で国の単語はわかりませんでした。 | S8: まだ練習中で体のパーツの単語はわかりませんでした。 | U8: まだ練習中で動詞の単語はわかりませんでした。 | Y8: まだ練習中で形容詞の単語はわかりませんでした。 | AA8: まだ練習中で現在形の動詞はわかりませんでした。 | AC8: まだ練習中で3級の単語はわかりませんでした。 | AE8: 1c1
B9: 30c2 | C9: 29c2 | D9: 28c2 | E9: 27c2 | F9: 26c2 | G9: 25c2 | H9: まだ練習中で自分の名前は言えませんでした。 | I9: 先生の後に続いてまねをしてお花の単語が言えました。 | J9: 先生の後に続いてまねをして食べ物の単語が言えました。 | K9: 先生の後に続いてまねをして曜日の単語が言えました。 | M9: 先生の後に続いてまねをして楽器の単語が言えました。 | O9: 先生の後に続いてまねをして体のパーツの単語が言えました。 | Q9: 先生の後に続いてまねをして国の単語が言えました。 | S9: 先生の後に続いてまねをして体のパーツの単語が言えました。 | U9: 先生の後に続いてまねをして動詞の単語が言えました。 | Y9: 先生の後に続いてまねをして形容詞の単語が言えました。 | AA9: 先生の後に続いてまねをして現在形の動詞が言えました。 | AC9: 先生の後に続いてまねをして3級の単語が言えました。 | AE9: 1c2
B10: 30c3 | C10: 29c3 | D10: 28c3 | E10: 27c3 | F10: 26c3 | G10: 25c3 | H10: 先生の後に続いてまねをして自分の名前が言えました。 | I10: お花の単語を英語で全て言えました！ | J10: 食べ物の単語を英語で全て言えました！ | K10: 曜日の単語を英語で全て言えました！ | M10: 楽器の単語を英語で全て言えました！ | O10: 体のパーツの単語を英語で全て言えました！ | Q10: 国の単語を英語で全て言えました！ | S10: 体のパーツの単語を英語で全て言えました！ | U10: 動詞の単語を英語で全て言えました！ | Y10: 形容詞の単語を英語で全て言えました！ | AA10: 現在形の動詞を英語で全て言えました！ | AC10: 3級の単語を英語で全て言えました！ | AE10: 1c3
B11: 30c4 | C11: 29c4 | D11: 28c4 | E11: 27c4 | F11: 26c4 | G11: 25c4 | H11: 自分の名前を英語で言えました！ | I11: お花についての単語はばっちり！質問もあと少しでカンペキでした。 | J11: 食べ物の単語はばっちり！質問もあと少しでカンペキでした。 | K11: 曜日についての単語はばっちり！質問もあと少しでカンペキでした。 | M11: 楽器の単語はばっちり！質問もあと少しでカンペキでした。 | O11: 体のパーツについての単語はばっちり！質問もあと少しでカンペキでした。 | Q11: 国の単語はばっちり！質問もあと少しでカンペキでした。 | S11: 体のパーツについての単語はばっちり！質問もあと少しでカンペキでした。 | U11: 動詞ついての単語はばっちり！質問もあと少しでカンペキでした。 | Y11: 形容詞の単語はばっちり！自分で作文するにはあと少しでした。 | AA11: 現在形の動詞はばっちり！自分で作文するにはあと少しでした。 | AC11: 3級の単語はばっちり！自分で作文するにはあと少しでした。 | AE11: 1c4
B12: 30c5 | C12: 29c5 | D12: 28c5 | E12: 27c5 | F12: 26c5 | G12: 25c5 | H12: I'm__.と文で自分の名前を言えました！Wonderful☆ | I12: お花についての質問・単語はばっちり！Wonderful☆ | J12: 食べ物についての質問(Do you want__?)・単語はばっちり！Wonderful☆ | K12: 曜日についての質問・単語はばっちり！Wonderful☆ | M12: 楽器についての質問(Do you like__?)・単語はばっちり！Wonderful☆ | O12: 体のパーツについての質問・単語はばっちり！Wonderful☆ | Q12: 国についての質問・単語はばっちり！Wonderful☆ | S12: 体のパーツについての質問・単語はばっちり！Wonderful☆ | U12: 動詞についての単語や質問①(Do you like to-?)はばっちり！Wonderful☆ | Y12: 形容詞の単語を入れて作文するのもばっちり！Wonderful☆ | AA12: 現在形の動詞と質問はばっちり！Wonderful☆ | AC12: 3級の単語を入れて作文するのもばっちり！Wonderful☆ | AE12: 1c5
B13: =IF($A$8=1,B8,IF($A$8=2,B9,IF($A$8=3,B10,IF($A$8=4,B11,IF($A$8=5,B12,"-"))))) -> 30c4 | C13: =IF($A$8=1,C8,IF($A$8=2,C9,IF($A$8=3,C10,IF($A$8=4,C11,IF($A$8=5,C12,"-"))))) -> 29c4 | D13: =IF($A$8=1,D8,IF($A$8=2,D9,IF($A$8=3,D10,IF($A$8=4,D11,IF($A$8=5,D12,"-"))))) -> 28c4 | E13: =IF($A$8=1,E8,IF($A$8=2,E9,IF($A$8=3,E10,IF($A$8=4,E11,IF($A$8=5,E12,"-"))))) -> 27c4 | F13: =IF($A$8=1,F8,IF($A$8=2,F9,IF($A$8=3,F10,IF($A$8=4,F11,IF($A$8=5,F12,"-"))))) -> 26c4 | G13: =IF($A$8=1,G8,IF($A$8=2,G9,IF($A$8=3,G10,IF($A$8=4,G11,IF($A$8=5,G12,"-"))))) -> 25c4 | H13: =IF($A$8=1,H8,IF($A$8=2,H9,IF($A$8=3,H10,IF($A$8=4,H11,IF($A$8=5,H12,"-"))))) -> 自分の名前を英語で言えました！ | I13: =IF($A$8=1,I8,IF($A$8=2,I9,IF($A$8=3,I10,IF($A$8=4,I11,IF($A$8=5,I12,"-"))))) -> お花についての単語はばっちり！質問もあと少しでカンペキでした。 | ... K13: =IF($A$8=1,K8,IF($A$8=2,K9,IF($A$8=3,K10,IF($A$8=4,K11,IF($A$8=5,K12,"-"))))) -> 曜日についての単語はばっちり！質問もあと少しでカンペキでした。 | M13: =IF($A$8=1,M8,IF($A$8=2,M9,IF($A$8=3,M10,IF($A$8=4,M11,IF($A$8=5,M12,"-"))))) -> 楽器の単語はばっちり！質問もあと少しでカンペキでした。 | O13: =IF($A$8=1,O8,IF($A$8=2,O9,IF($A$8=3,O10,IF($A$8=4,O11,IF($A$8=5,O12,"-"))))) -> 体のパーツについての単語はばっちり！質問もあと少しでカンペキでした。 | Q13: =IF($A$8=1,Q8,IF($A$8=2,Q9,IF($A$8=3,Q10,IF($A$8=4,Q11,IF($A$8=5,Q12,"-"))))) -> 国の単語はばっちり！質問もあと少しでカンペキでした。 | S13: =IF($A$8=1,S8,IF($A$8=2,S9,IF($A$8=3,S10,IF($A$8=4,S11,IF($A$8=5,S12,"-"))))) -> 体のパーツについての単語はばっちり！質問もあと少しでカンペキでした。 | U13: =IF($A$8=1,U8,IF($A$8=2,U9,IF($A$8=3,U10,IF($A$8=4,U11,IF($A$8=5,U12,"-"))))) -> 動詞ついての単語はばっちり！質問もあと少しでカンペキでした。 | Y13: =IF($A$8=1,Y8,IF($A$8=2,Y9,IF($A$8=3,Y10,IF($A$8=4,Y11,IF($A$8=5,Y12,"-"))))) -> 形容詞の単語はばっちり！自分で作文するにはあと少しでした。 | AA13: =IF($A$8=1,AA8,IF($A$8=2,AA9,IF($A$8=3,AA10,IF($A$8=4,AA11,IF($A$8=5,AA12,"-"))))) -> 現在形の動詞はばっちり！自分で作文するにはあと少しでした。 | AC13: =IF($A$8=1,AC8,IF($A$8=2,AC9,IF($A$8=3,AC10,IF($A$8=4,AC11,IF($A$8=5,AC12,"-"))))) -> 3級の単語はばっちり！自分で作文するにはあと少しでした。 | AE13: =IF($A$8=1,AE8,IF($A$8=2,AE9,IF($A$8=3,AE10,IF($A$8=4,AE11,IF($A$8=5,AE12,"-"))))) -> 1c4
A14: =score!E2 -> 5 | B14: 30c1 | C14: 29c1 | D14: 28c1 | E14: 27c1 | F14: 26c1 | G14: 25c1 | H14: 残念ながら、緊張してしまったのかフォニックスの歌を聞くことができませんでした。 | I14: まだ練習中で野菜の単語はわかりませんでした。 | J14: まだ練習中で持ち物の単語はわかりませんでした。 | K14: まだ練習中で反対言葉の単語はわかりませんでした。 | M14: まだ練習中でスポーツの単語はわかりませんでした。 | O14: まだ練習中で季節の単語はわかりませんでした。 | Q14: まだ練習中で自分の出身について言えませんでした。 | S14: まだ練習中で症状の単語はわかりませんでした。 | Y14: まだ練習中で関連語・表現はわかりませんでした。 | AA14: まだ練習中で過去形の動詞はわかりませんでした。 | AC14: まだ練習中でifを使った質問には答えられませんでした。 | AE14: 1c1
B15: 30c2 | C15: 29c2 | D15: 28c2 | E15: 27c2 | F15: 26c2 | G15: 25c2 | H15: まだ練習中でフォニックスの歌を歌えませんでした。 | I15: 先生の後に続いてまねをして野菜の単語が言えました。 | J15: 先生の後に続いてまねをして持ち物の単語が言えました。 | K15: 先生の後に続いてまねをして反対言葉の単語が言えました。 | M15: 先生の後に続いてまねをしてスポーツの単語が言えました。 | O15: 先生の後に続いてまねをして季節の単語が言えました。 | Q15: 先生の後に続いてまねをして自分の出身が言えました。 | S15: 先生の後に続いてまねをして症状の単語が言えました。 | Y15: 先生の後に続いてまねをして関連語・表現が言えました。 | AA15: 先生の後に続いてまねをして過去形の動詞が言えました。 | AC15: 先生の後に続いてまねをしてifを使った質問に答えることができました。 | AE15: 1c2
B16: 30c3 | C16: 29c3 | D16: 28c3 | E16: 27c3 | F16: 26c3 | G16: 25c3 | H16: 先生の後に続いてまねをしてフォニックスの歌が歌えました。 | I16: 野菜の単語を英語で全て言えました！ | J16: 持ち物の単語を英語で全て言えました！ | K16: 反対言葉の単語を英語で全て言えました！ | M16: スポーツの単語を英語で全て言えました！ | O16: 季節の単語を英語で全て言えました！ | Q16: 自分の出身について先生の質問に何とか答えられました！ | S16: 症状の単語を英語で全て言えました！ | Y16: 関連語・表現を英語で全て言えました！ | AA16: 過去形の動詞を英語で全て言えました！ | AC16: ifを使った質問に単語だけで何とか答えることができました。 | AE16: 1c3
B17: 30c4 | C17: 29c4 | D17: 28c4 | E17: 27c4 | F17: 26c4 | G17: 25c4 | H17: がんばってフォニックスの歌を歌えました！ | I17: 野菜の単語はばっちり！質問もあと少しでカンペキでした。 | J17: 持ち物の単語はばっちり！質問もあと少しでカンペキでした。 | K17: 反対言葉についての単語はばっちり！質問もあと少しでカンペキでした。 | M17: スポーツの単語はばっちり！質問もあと少しでカンペキでした。 | O17: 季節についての単語はばっちり！質問もあと少しでカンペキでした。 | Q17: 自分の出身について先生の質問にスムーズに答えれことができます！次は文でI'm from__.と文で言えるように先生と練習しよう。 | S17: 症状についての単語はばっちり！質問もあと少しでカンペキでした。 | Y17: 関連語・表現はばっちり！自分で作文するにはあと少しでした。 | AA17: 過去形の動詞はばっちり！自分で作文するにはあと少しでした。 | AC17: ifを使った質問に答えることができました。 | AE17: 1c4
B18: 30c5 | C18: 29c5 | D18: 28c5 | E18: 27c5 | F18: 26c5 | G18: 25c5 | H18: フォニックスの歌は完ぺきでした！Amazing☆ | I18: 野菜についての質問・単語はばっちり！Amazing☆ | J18: 持ち物についての質問(Do you wamt__?)・単語はばっちり！Amazing☆ | K18: 反対言葉についての質問・単語はばっちり！Amazing☆ | M18: スポーツについての質問(Can you__?)・単語はばっちり！Amazing☆ | O18: 季節についての質問・単語はばっちり！Amazing☆ | Q18: 自分の出身について先生の質問に文で完ぺきに答えられます！Amazing☆ | S18: 症状についての質問・単語はばっちり！Amazing☆ | U18: 動詞についての質問②(Did you-?)もばっちり！Amazing☆ | Y18: 関連語・表現を入れて作文するのもばっちり！Amazing☆ | AA18: 過去形の動詞と質問もばっちり！Amazing☆ | AC18: ifを使った質問に理由を添えて答えることができました！Amazing☆ | AE18: 1c5
B19: =IF($A$14=1,B14,IF($A$14=2,B15,IF($A$14=3,B16,IF($A$14=4,B17,IF($A$14=5,B18,"-"))))) -> 30c5 | C19: =IF($A$14=1,C14,IF($A$14=2,C15,IF($A$14=3,C16,IF($A$14=4,C17,IF($A$14=5,C18,"-"))))) -> 29c5 | D19: =IF($A$14=1,D14,IF($A$14=2,D15,IF($A$14=3,D16,IF($A$14=4,D17,IF($A$14=5,D18,"-"))))) -> 28c5 | E19: =IF($A$14=1,E14,IF($A$14=2,E15,IF($A$14=3,E16,IF($A$14=4,E17,IF($A$14=5,E18,"-"))))) -> 27c5 | F19: =IF($A$14=1,F14,IF($A$14=2,F15,IF($A$14=3,F16,IF($A$14=4,F17,IF($A$14=5,F18,"-"))))) -> 26c5 | G19: =IF($A$14=1,G14,IF($A$14=2,G15,IF($A$14=3,G16,IF($A$14=4,G17,IF($A$14=5,G18,"-"))))) -> 25c5 | H19: =IF($A$14=1,H14,IF($A$14=2,H15,IF($A$14=3,H16,IF($A$14=4,H17,IF($A$14=5,H18,"-"))))) -> フォニックスの歌は完ぺきでした！Amazing☆ | I19: =IF($A$14=1,I14,IF($A$14=2,I15,IF($A$14=3,I16,IF($A$14=4,I17,IF($A$14=5,I18,"-"))))) -> 野菜についての質問・単語はばっちり！Amazing☆ | ... K19: =IF($A$14=1,K14,IF($A$14=2,K15,IF($A$14=3,K16,IF($A$14=4,K17,IF($A$14=5,K18,"-"))))) -> 反対言葉についての質問・単語はばっちり！Amazing☆ | M19: =IF($A$14=1,M14,IF($A$14=2,M15,IF($A$14=3,M16,IF($A$14=4,M17,IF($A$14=5,M18,"-"))))) -> スポーツについての質問(Can you__?)・単語はばっちり！Amazing☆ | O19: =IF($A$14=1,O14,IF($A$14=2,O15,IF($A$14=3,O16,IF($A$14=4,O17,IF($A$14=5,O18,"-"))))) -> 季節についての質問・単語はばっちり！Amazing☆ | Q19: =IF($A$14=1,Q14,IF($A$14=2,Q15,IF($A$14=3,Q16,IF($A$14=4,Q17,IF($A$14=5,Q18,"-"))))) -> 自分の出身について先生の質問に文で完ぺきに答えられます！Amazing☆ | S19: =IF($A$14=1,S14,IF($A$14=2,S15,IF($A$14=3,S16,IF($A$14=4,S17,IF($A$14=5,S18,"-"))))) -> 症状についての質問・単語はばっちり！Amazing☆ | U19: =IF($A$14=1,U14,IF($A$14=2,U15,IF($A$14=3,U16,IF($A$14=4,U17,IF($A$14=5,U18,"-"))))) -> 動詞についての質問②(Did you-?)もばっちり！Amazing☆ | Y19: =IF($A$14=1,Y14,IF($A$14=2,Y15,IF($A$14=3,Y16,IF($A$14=4,Y17,IF($A$14=5,Y18,"-"))))) -> 関連語・表現を入れて作文するのもばっちり！Amazing☆ | AA19: =IF($A$14=1,AA14,IF($A$14=2,AA15,IF($A$14=3,AA16,IF($A$14=4,AA17,IF($A$14=5,AA18,"-"))))) -> 過去形の動詞と質問もばっちり！Amazing☆ | AC19: =IF($A$14=1,AC14,IF($A$14=2,AC15,IF($A$14=3,AC16,IF($A$14=4,AC17,IF($A$14=5,AC18,"-"))))) -> ifを使った質問に理由を添えて答えることができました！Amazing☆ | AE19: =IF($A$14=1,AE14,IF($A$14=2,AE15,IF($A$14=3,AE16,IF($A$14=4,AE17,IF($A$14=5,AE18,"-"))))) -> 1c5
A20: =score!F2 -> 5 | B20: 30c1 | C20: 29c1 | D20: 28c1 | E20: 27c1 | F20: 26c1 | G20: 25c1 | H20: 残念ながら、緊張してしまったのか色についての質問を聞くことができませんでした。 | I20: まだ練習中でおもちゃの単語はわかりませんでした。 | J20: まだ練習中でキッチン周りの道具の単語はわかりませんでした。 | K20: まだ練習中で天気の単語はわかりませんでした。 | M20: まだ練習中で動きを表す単語はわかりませんでした。 | O20: まだ練習中で月日の単語はわかりませんでした。 | Q20: まだ練習中で各国の象徴的なものの単語はわかりませんでした。 | S20: まだ練習中で動詞の単語はわかりませんでした。 | U20: まだ練習中で趣味の単語はわかりませんでした。 | Y20: まだ練習中で比較を表す単語はわかりませんでした。 | AA20: まだ練習中で現在完了形の動詞はわかりませんでした。 | AC20: まだ練習中でifを使った質問②には答えられませんでした。 | AE20: 1c1
B21: 30c2 | C21: 29c2 | D21: 28c2 | E21: 27c2 | F21: 26c2 | G21: 25c2 | H21: まだ練習中で色を英語で言えませんでした。 | I21: 先生の後に続いてまねをしておもちゃの単語が言えました。 | J21: 先生の後に続いてまねをしてキッチン周りの道具の単語が言えました。 | K21: 先生の後に続いてまねをして天気の単語が言えました。 | M21: 先生の後に続いてまねをして動きを表す単語が言えました。 | O21: 先生の後に続いてまねをして月日の単語が言えました。 | Q21: 先生の後に続いてまねをして各国の象徴的なものの単語が言えました。 | S21: 先生の後に続いてまねをして動詞の単語が言えました。 | U21: 先生の後に続いてまねをして趣味の単語が言えました。 | Y21: 先生の後に続いてまねをして比較を表す単語が言えました。 | AA21: 先生の後に続いてまねをして現在完了形の動詞が言えました。 | AC21: 先生の後に続いてまねをしてifを使った質問②に答えることができました。 | AE21: 1c2
B22: 30c3 | C22: 29c3 | D22: 28c3 | E22: 27c3 | F22: 26c3 | G22: 25c3 | H22: 先生の後に続いてまねをして色が英語で言えました。 | I22: おもちゃの単語を英語で全て言えました！ | J22: キッチン周りの道具の単語を英語で全て言えました！ | K22: 天気の単語を英語で全て言えました！ | M22: 動きを表す単語を英語で全て言えました！ | O22: 月日の単語を英語で全て言えました！ | Q22: 各国の象徴的なものの単語を英語で全て言えました！ | S22: 動詞の単語を英語で全て言えました！ | U22: 趣味の単語を英語で全て言えました！ | Y22: 比較を表す単語を英語で全て言えました！ | AA22: 現在完了形の動詞を英語で全て言えました！ | AC22: ifを使った質問②に単語だけで何とか答えることができました。 | AE22: 1c3
B23: 30c4 | C23: 29c4 | D23: 28c4 | E23: 27c4 | F23: 26c4 | G23: 25c4 | H23: ほとんどの色を英語で言えました！ | I23: おもちゃの単語はばっちり！質問もあと少しでカンペキでした。 | J23: キッチン周りの道具の単語はばっちり！質問もあと少しでカンペキでした。 | K23: 天気についての単語はばっちり！質問もあと少しでカンペキでした。 | M23: 動きを表す単語はばっちり！質問もあと少しでカンペキでした。 | O23: 月日についての単語はばっちり！質問もあと少しでカンペキでした。 | Q23: 各国の象徴的なものの単語はばっちり！質問もあと少しでカンペキでした。 | S23: 動詞の単語はばっちり！質問もあと少しでカンペキでした。 | U23: 趣味ついての単語はばっちり！質問もあと少しでカンペキでした。 | Y23: 比較を表す単語はばっちり！自分で作文するにはあと少しでした。 | AA23: 現在完了形の動詞はばっちり！自分で作文するにはあと少しでした。 | AC23: ifを使った質問②に答えることができました。 | AE23: 1c4
B24: 30c5 | C24: 29c5 | D24: 28c5 | E24: 27c5 | F24: 26c5 | G24: 25c5 | H24: すべての色を英語で言えました！Brilliant☆ | I24: おもちゃについての質問・単語はばっちり！Brilliant☆ | J24: キッチン周りの道具についての質問(Do you need__?)・単語はばっちり！Brilliant☆ | K24: 天気についての質問・単語はばっちり！Brilliant☆ | M24: 動きを表す単語とそれを使った質問(Can you__?)もばっちり！Brilliant☆ | O24: 月日についての質問・単語はばっちり！Brilliant☆ | Q24: 各国の象徴的なものの国についての質問・単語はばっちり！Brilliant☆ | S24: 動詞の入った質問・単語はばっちり！Brilliant☆ | U24: 趣味についての質問・単語はばっちり！Brilliant☆ | Y24: 比較表現を入れて作文するのもばっちり！Brilliant☆ | AA24: 現在完了形の動詞と質問①(Have you-?)もばっちり！Brilliant☆ | AC24: ifを使った質問②に理由を添えて答えることができました！Brilliant☆ | AE24: 1c5
B25: =IF($A$20=1,B20,IF($A$20=2,B21,IF($A$20=3,B22,IF($A$20=4,B23,IF($A$20=5,B24,"-"))))) -> 30c5 | C25: =IF($A$20=1,C20,IF($A$20=2,C21,IF($A$20=3,C22,IF($A$20=4,C23,IF($A$20=5,C24,"-"))))) -> 29c5 | D25: =IF($A$20=1,D20,IF($A$20=2,D21,IF($A$20=3,D22,IF($A$20=4,D23,IF($A$20=5,D24,"-"))))) -> 28c5 | E25: =IF($A$20=1,E20,IF($A$20=2,E21,IF($A$20=3,E22,IF($A$20=4,E23,IF($A$20=5,E24,"-"))))) -> 27c5 | F25: =IF($A$20=1,F20,IF($A$20=2,F21,IF($A$20=3,F22,IF($A$20=4,F23,IF($A$20=5,F24,"-"))))) -> 26c5 | G25: =IF($A$20=1,G20,IF($A$20=2,G21,IF($A$20=3,G22,IF($A$20=4,G23,IF($A$20=5,G24,"-"))))) -> 25c5 | H25: =IF($A$20=1,H20,IF($A$20=2,H21,IF($A$20=3,H22,IF($A$20=4,H23,IF($A$20=5,H24,"-"))))) -> すべての色を英語で言えました！Brilliant☆ | I25: =IF($A$20=1,I20,IF($A$20=2,I21,IF($A$20=3,I22,IF($A$20=4,I23,IF($A$20=5,I24,"-"))))) -> おもちゃについての質問・単語はばっちり！Brilliant☆ | ... K25: =IF($A$20=1,K20,IF($A$20=2,K21,IF($A$20=3,K22,IF($A$20=4,K23,IF($A$20=5,K24,"-"))))) -> 天気についての質問・単語はばっちり！Brilliant☆ | M25: =IF($A$20=1,M20,IF($A$20=2,M21,IF($A$20=3,M22,IF($A$20=4,M23,IF($A$20=5,M24,"-"))))) -> 動きを表す単語とそれを使った質問(Can you__?)もばっちり！Brilliant☆ | O25: =IF($A$20=1,O20,IF($A$20=2,O21,IF($A$20=3,O22,IF($A$20=4,O23,IF($A$20=5,O24,"-"))))) -> 月日についての質問・単語はばっちり！Brilliant☆ | Q25: =IF($A$20=1,Q20,IF($A$20=2,Q21,IF($A$20=3,Q22,IF($A$20=4,Q23,IF($A$20=5,Q24,"-"))))) -> 各国の象徴的なものの国についての質問・単語はばっちり！Brilliant☆ | S25: =IF($A$20=1,S20,IF($A$20=2,S21,IF($A$20=3,S22,IF($A$20=4,S23,IF($A$20=5,S24,"-"))))) -> 動詞の入った質問・単語はばっちり！Brilliant☆ | U25: =IF($A$20=1,U20,IF($A$20=2,U21,IF($A$20=3,U22,IF($A$20=4,U23,IF($A$20=5,U24,"-"))))) -> 趣味についての質問・単語はばっちり！Brilliant☆ | Y25: =IF($A$20=1,Y20,IF($A$20=2,Y21,IF($A$20=3,Y22,IF($A$20=4,Y23,IF($A$20=5,Y24,"-"))))) -> 比較表現を入れて作文するのもばっちり！Brilliant☆ | AA25: =IF($A$20=1,AA20,IF($A$20=2,AA21,IF($A$20=3,AA22,IF($A$20=4,AA23,IF($A$20=5,AA24,"-"))))) -> 現在完了形の動詞と質問①(Have you-?)もばっちり！Brilliant☆ | AC25: =IF($A$20=1,AC20,IF($A$20=2,AC21,IF($A$20=3,AC22,IF($A$20=4,AC23,IF($A$20=5,AC24,"-"))))) -> ifを使った質問②に理由を添えて答えることができました！Brilliant☆ | AE25: =IF($A$20=1,AE20,IF($A$20=2,AE21,IF($A$20=3,AE22,IF($A$20=4,AE23,IF($A$20=5,AE24,"-"))))) -> 1c5
A26: =score!G2 -> 5 | B26: 30c1 | C26: 29c1 | D26: 28c1 | E26: 27c1 | F26: 26c1 | G26: 25c1 | H26: 残念ながら、緊張してしまったのか乗り物についての質問を聞くことができませんでした。 | I26: まだ練習中でお花を使ったHow manyの質問には答えられませんでした。 | K26: まだ練習中で衣類の単語はわかりませんでした。 | O26: まだ練習中で年間行事の単語はわかりませんでした。 | Q26: まだ練習中で各国の有名なものの単語はわかりませんでした。 | S26: まだ練習中で関連語の単語はわかりませんでした。 | U26: まだ練習中で形容詞の単語はわかりませんでした。 | Y26: まだ練習中で最上級を表す単語はわかりませんでした。 | AC26: まだ練習中で付加疑問を表す質問には答えられませんでした。 | AE26: 1c1
B27: 30c2 | C27: 29c2 | D27: 28c2 | E27: 27c2 | F27: 26c2 | G27: 25c2 | H27: まだ練習中で乗り物を英語で言えませんでした。 | I27: お花の単語はわかりましたが、お花を使ったHow manyの質問には答えられませんでした。 | K27: 先生の後に続いてまねをして衣類の単語が言えました。 | O27: 先生の後に続いてまねをして年間行事の単語が言えました。 | Q27: 先生の後に続いてまねをして各国の有名なものの単語が言えました。 | S27: 先生の後に続いてまねをして関連語の単語が言えました。 | U27: 先生の後に続いてまねをして形容詞の単語が言えました。 | Y27: 先生の後に続いてまねをして最上級を表す単語が言えました。 | AC27: 先生の後に続いてまねをして付加疑問を表す質問に答えることができました。 | AE27: 1c2
B28: 30c3 | C28: 29c3 | D28: 28c3 | E28: 27c3 | F28: 26c3 | G28: 25c3 | H28: 先生の後に続いてまねをして乗り物が英語で言えました。 | I28: 先生の後に続いてまねをしてお花を使ったHow manyの質問に答えることができました。 | K28: 衣類の単語を英語で全て言えました！ | O28: 年間行事の単語を英語で全て言えました！ | Q28: 各国の有名なものの単語を英語で全て言えました！ | S28: 関連語の単語を英語で全て言えました！ | U28: 形容詞の単語を英語で全て言えました！ | Y28: 最上級を表す単語を英語で全て言えました！ | AC28: 付加疑問を表す質問に何とか答えることができました。 | AE28: 1c3
B29: 30c4 | C29: 29c4 | D29: 28c4 | E29: 27c4 | F29: 26c4 | G29: 25c4 | H29: ほとんどの乗り物を英語で言えました！ | I29: お花を使ったHow manyの質問に何とか答えることができました。 | J29: さらに"What can you want?"に対して、単語で答えることができました。 | K29: 衣類についての単語はばっちり！質問もあと少しでカンペキでした。 | M29: さらに"What can you do?"に対して、単語で答えることができました。 | O29: 年間行事についての単語はばっちり！質問もあと少しでカンペキでした。 | Q29: 各国の有名なものの単語はばっちり！質問もあと少しでカンペキでした。 | S29: 関連語の単語はばっちり！質問もあと少しでカンペキでした。 | U29: 形容詞の単語はばっちり！質問もあと少しでカンペキでした。 | Y29: 最上級を表す単語はばっちり！自分で作文するにはあと少しでした。 | AC29: 付加疑問を表す質問を何とか自分で作ることできました。 | AE29: 1c4
B30: 30c5 | C30: 29c5 | D30: 28c5 | E30: 27c5 | F30: 26c5 | G30: 25c5 | H30: すべての乗り物を英語で言えました！Awesome☆ | I30: お花を使ったHow manyの質問にもばっちり答えられました！Awesome☆ | J30: さらに"What can you want?"に対して、"I want__."と文で答えることができました！Awesome☆ | K30: 衣類についての質問・単語はばっちり！Awesome☆ | M30: さらに"What can you do?"に対して、"I can__."と文で答えることができました！Awesome☆ | O30: 年間行事についての質問・単語はばっちり！Awesome☆ | Q30: 各国の有名なものの国についての質問・単語はばっちり！Awesome☆ | S30: 関連語の入った質問・単語はばっちり！Awesome☆ | U30: 形容詞の入った質問・単語はばっちり！Awesome☆ | Y30: 最上級を入れて作文するのもばっちり！Awesome☆ | AA30: 現在完了形の動詞と質問②(How long have you-?)もばっちり！Awesome☆ | AC30: 付加疑問を表す質問を自分でカンペキに作ることができました！Awesome☆ | AE30: 1c5
B31: =IF($A$26=1,B26,IF($A$26=2,B27,IF($A$26=3,B28,IF($A$26=4,B29,IF($A$26=5,B30,"-"))))) -> 30c5 | C31: =IF($A$26=1,C26,IF($A$26=2,C27,IF($A$26=3,C28,IF($A$26=4,C29,IF($A$26=5,C30,"-"))))) -> 29c5 | D31: =IF($A$26=1,D26,IF($A$26=2,D27,IF($A$26=3,D28,IF($A$26=4,D29,IF($A$26=5,D30,"-"))))) -> 28c5 | E31: =IF($A$26=1,E26,IF($A$26=2,E27,IF($A$26=3,E28,IF($A$26=4,E29,IF($A$26=5,E30,"-"))))) -> 27c5 | F31: =IF($A$26=1,F26,IF($A$26=2,F27,IF($A$26=3,F28,IF($A$26=4,F29,IF($A$26=5,F30,"-"))))) -> 26c5 | G31: =IF($A$26=1,G26,IF($A$26=2,G27,IF($A$26=3,G28,IF($A$26=4,G29,IF($A$26=5,G30,"-"))))) -> 25c5 | H31: =IF($A$26=1,H26,IF($A$26=2,H27,IF($A$26=3,H28,IF($A$26=4,H29,IF($A$26=5,H30,"-"))))) -> すべての乗り物を英語で言えました！Awesome☆ | I31: =IF($A$26=1,I26,IF($A$26=2,I27,IF($A$26=3,I28,IF($A$26=4,I29,IF($A$26=5,I30,"-"))))) -> お花を使ったHow manyの質問にもばっちり答えられました！Awesome☆ | ... K31: =IF($A$26=1,K26,IF($A$26=2,K27,IF($A$26=3,K28,IF($A$26=4,K29,IF($A$26=5,K30,"-"))))) -> 衣類についての質問・単語はばっちり！Awesome☆ | M31: =IF($A$26=1,M26,IF($A$26=2,M27,IF($A$26=3,M28,IF($A$26=4,M29,IF($A$26=5,M30,"-"))))) -> さらに"What can you do?"に対して、"I can__."と文で答えることができました！Awesome☆ | O31: =IF($A$26=1,O26,IF($A$26=2,O27,IF($A$26=3,O28,IF($A$26=4,O29,IF($A$26=5,O30,"-"))))) -> 年間行事についての質問・単語はばっちり！Awesome☆ | Q31: =IF($A$26=1,Q26,IF($A$26=2,Q27,IF($A$26=3,Q28,IF($A$26=4,Q29,IF($A$26=5,Q30,"-"))))) -> 各国の有名なものの国についての質問・単語はばっちり！Awesome☆ | S31: =IF($A$26=1,S26,IF($A$26=2,S27,IF($A$26=3,S28,IF($A$26=4,S29,IF($A$26=5,S30,"-"))))) -> 関連語の入った質問・単語はばっちり！Awesome☆ | U31: =IF($A$26=1,U26,IF($A$26=2,U27,IF($A$26=3,U28,IF($A$26=4,U29,IF($A$26=5,U30,"-"))))) -> 形容詞の入った質問・単語はばっちり！Awesome☆ | Y31: =IF($A$26=1,Y26,IF($A$26=2,Y27,IF($A$26=3,Y28,IF($A$26=4,Y29,IF($A$26=5,Y30,"-"))))) -> 最上級を入れて作文するのもばっちり！Awesome☆ | AA31: =IF($A$26=1,AA26,IF($A$26=2,AA27,IF($A$26=3,AA28,IF($A$26=4,AA29,IF($A$26=5,AA30,"-"))))) -> 現在完了形の動詞と質問②(How long have you-?)もばっちり！Awesome☆ | AC31: =IF($A$26=1,AC26,IF($A$26=2,AC27,IF($A$26=3,AC28,IF($A$26=4,AC29,IF($A$26=5,AC30,"-"))))) -> 付加疑問を表す質問を自分でカンペキに作ることができました！Awesome☆ | AE31: =IF($A$26=1,AE26,IF($A$26=2,AE27,IF($A$26=3,AE28,IF($A$26=4,AE29,IF($A$26=5,AE30,"-"))))) -> 1c5
A32: =score!H2 -> 4 | B32: 30c1 | C32: 29c1 | D32: 28c1 | E32: 27c1 | F32: 26c1 | G32: 25c1 | H32: 残念ながら、緊張してしまったのか虫についての質問を聞くことができませんでした。 | I32: まだ練習中で野菜を使ったHow muchの質問には答えられませんでした。 | K32: まだ練習中でジーンズなどの数え方や服のサイズはわかりませんでした。 | M32: まだ練習中で家族と性格の単語はわかりませんでした。 | O32: まだ練習中で食べ物の特徴についての単語はわかりませんでした。 | Q32: まだ練習中で複数形の単語はわかりませんでした。 | S32: まだ練習中でDoesを使った質問には答えられませんでした。 | U32: まだ練習中で関連語の単語はわかりませんでした。 | Y32: まだ練習中でその他比較表現の入った質問には答えられませんでした。 | AC32: まだ練習中で間接疑問を表す質問には答えられませんでした。 | AE32: 1c1
B33: 30c2 | C33: 29c2 | D33: 28c2 | E33: 27c2 | F33: 26c2 | G33: 25c2 | H33: まだ練習中で虫を英語で言えませんでした。 | I33: 野菜の単語はわかりましたが、野菜を使ったHow muchの質問には答えられませんでした。 | K33: 先生の後に続いてまねをしてジーンズなどの数え方や服のサイズが言えました。 | M33: 先生の後に続いてまねをして家族と性格の単語が言えました。 | O33: 先生の後に続いてまねをして食べ物の特徴についての単語が言えました。 | Q33: 先生の後に続いてまねをして複数形の単語が言えました。 | S33: 先生の後に続いてまねをしてDoesを使った質問に答えることができました。 | U33: 先生の後に続いてまねをして関連語の単語が言えました。 | Y33: 先生の後に続いてまねをしてその他比較表現の入った質問に答えることができました。 | AC33: 先生の後に続いてまねをして間接疑問を表す質問に答えることができました。 | AE33: 1c2
B34: 30c3 | C34: 29c3 | D34: 28c3 | E34: 27c3 | F34: 26c3 | G34: 25c3 | H34: 先生の後に続いてまねをして虫が英語で言えました。 | I34: 先生の後に続いてまねをして野菜を使ったHow muchの質問に答えることができました。 | K34: ジーンズなどの数え方や服のサイズを英語で全て言えました！ | M34: 家族と性格の単語を英語で全て言えました！ | O34: 食べ物の特徴についての単語を英語で全て言えました！ | Q34: 複数形の単語を英語で全て言えました！ | S34: Doesを使った質問にも何とか答えることができました！ | U34: 関連語の単語を英語で全て言えました！ | Y34: その他比較表現の入った質問に何とかいくつか答えることができました。 | AC34: 間接疑問を表す質問に何とか答えることができました。 | AE34: 1c3
B35: 30c4 | C35: 29c4 | D35: 28c4 | E35: 27c4 | F35: 26c4 | G35: 25c4 | H35: ほとんどの虫を英語で言えました！ | I35: 野菜を使ったHow muchの質問に何とか答えることができました。 | J35: さらに"What can you need?"に対して、単語で答えることができました。 | K35: ジーンズなどの数え方や服のサイズはばっちり！質問もあと少しでカンペキでした。 | M35: 家族と性格の単語はばっちり！質問もあと少しでカンペキでした。 | O35: 食べ物の特徴についての単語はばっちり！質問もあと少しでカンペキでした。 | Q35: 複数形の単語はばっちり！質問もあと少しでカンペキでした。 | S35: Doesを使った全ての質問にYes, Noで答えることができました。 | U35: 関連語の単語はばっちり！Why?の質問もあと少しでカンペキでした。 | Y35: その他比較表現の入った質問にもいくつか答えることができました！ | AC35: 間接疑問を表す質問を何とか自分で作ることできました。 | AE35: 1c4
B36: 30c5 | C36: 29c5 | D36: 28c5 | E36: 27c5 | F36: 26c5 | G36: 25c5 | H36: すべての虫を英語で言えました！Fantastic☆ | I36: 野菜を使ったHow muchの質問にもばっちり答えられました！Fantastic☆ | J36: さらに"What can you need?"に対して、"I need__."と文で答えることができました！Fantastic☆ | K36: ジーンズなどの数え方や服のサイズについての質問・単語はばっちり！Fantastic☆ | M36: 家族と性格ついての質問・単語はばっちり！Fantastic☆ | O36: 食べ物の特徴についての質問・単語はばっちり！Fantastic☆ | Q36: 複数形についての質問・単語はばっちり！Fantastic☆ | S36: Doesを使った全ての質問にばっちり文で答えられました！Fantastic☆ | U36: 関連語の単語も、Why?の質問に対する答えもばっちり！Fantastic☆ | Y36: その他比較表現の入った質問に答えたり作文したりできました！Fantastic☆ | AA36: 現在完了形の動詞と質問③(How many times have you-?)もばっちり！Fantastic☆ | AC36: 間接疑問を表す質問を自分でカンペキに作ることができました！Fantastic☆ | AE36: 1c5
B37: =IF($A$32=1,B32,IF($A$32=2,B33,IF($A$32=3,B34,IF($A$32=4,B35,IF($A$32=5,B36,"-"))))) -> 30c4 | C37: =IF($A$32=1,C32,IF($A$32=2,C33,IF($A$32=3,C34,IF($A$32=4,C35,IF($A$32=5,C36,"-"))))) -> 29c4 | D37: =IF($A$32=1,D32,IF($A$32=2,D33,IF($A$32=3,D34,IF($A$32=4,D35,IF($A$32=5,D36,"-"))))) -> 28c4 | E37: =IF($A$32=1,E32,IF($A$32=2,E33,IF($A$32=3,E34,IF($A$32=4,E35,IF($A$32=5,E36,"-"))))) -> 27c4 | F37: =IF($A$32=1,F32,IF($A$32=2,F33,IF($A$32=3,F34,IF($A$32=4,F35,IF($A$32=5,F36,"-"))))) -> 26c4 | G37: =IF($A$32=1,G32,IF($A$32=2,G33,IF($A$32=3,G34,IF($A$32=4,G35,IF($A$32=5,G36,"-"))))) -> 25c4 | H37: =IF($A$32=1,H32,IF($A$32=2,H33,IF($A$32=3,H34,IF($A$32=4,H35,IF($A$32=5,H36,"-"))))) -> ほとんどの虫を英語で言えました！ | I37: =IF($A$32=1,I32,IF($A$32=2,I33,IF($A$32=3,I34,IF($A$32=4,I35,IF($A$32=5,I36,"-"))))) -> 野菜を使ったHow muchの質問に何とか答えることができました。 | ... K37: =IF($A$32=1,K32,IF($A$32=2,K33,IF($A$32=3,K34,IF($A$32=4,K35,IF($A$32=5,K36,"-"))))) -> ジーンズなどの数え方や服のサイズはばっちり！質問もあと少しでカンペキでした。 | M37: =IF($A$32=1,M32,IF($A$32=2,M33,IF($A$32=3,M34,IF($A$32=4,M35,IF($A$32=5,M36,"-"))))) -> 家族と性格の単語はばっちり！質問もあと少しでカンペキでした。 | O37: =IF($A$32=1,O32,IF($A$32=2,O33,IF($A$32=3,O34,IF($A$32=4,O35,IF($A$32=5,O36,"-"))))) -> 食べ物の特徴についての単語はばっちり！質問もあと少しでカンペキでした。 | Q37: =IF($A$32=1,Q32,IF($A$32=2,Q33,IF($A$32=3,Q34,IF($A$32=4,Q35,IF($A$32=5,Q36,"-"))))) -> 複数形の単語はばっちり！質問もあと少しでカンペキでした。 | S37: =IF($A$32=1,S32,IF($A$32=2,S33,IF($A$32=3,S34,IF($A$32=4,S35,IF($A$32=5,S36,"-"))))) -> Doesを使った全ての質問にYes, Noで答えることができました。 | U37: =IF($A$32=1,U32,IF($A$32=2,U33,IF($A$32=3,U34,IF($A$32=4,U35,IF($A$32=5,U36,"-"))))) -> 関連語の単語はばっちり！Why?の質問もあと少しでカンペキでした。 | Y37: =IF($A$32=1,Y32,IF($A$32=2,Y33,IF($A$32=3,Y34,IF($A$32=4,Y35,IF($A$32=5,Y36,"-"))))) -> その他比較表現の入った質問にもいくつか答えることができました！ | AA37: =IF($A$32=1,AA32,IF($A$32=2,AA33,IF($A$32=3,AA34,IF($A$32=4,AA35,IF($A$32=5,AA36,"-"))))) | AC37: =IF($A$32=1,AC32,IF($A$32=2,AC33,IF($A$32=3,AC34,IF($A$32=4,AC35,IF($A$32=5,AC36,"-"))))) -> 間接疑問を表す質問を何とか自分で作ることできました。 | AE37: =IF($A$32=1,AE32,IF($A$32=2,AE33,IF($A$32=3,AE34,IF($A$32=4,AE35,IF($A$32=5,AE36,"-"))))) -> 1c4
A38: =score!I2 -> 4 | B38: 30c1 | C38: 29c1 | D38: 28c1 | E38: 27c1 | F38: 26c1 | G38: 25c1 | H38: フォニックスの読み書きはまだ練習中でわかりませんでした。 | I38: フォニックスの読み書きはまだ練習中でわかりませんでした。 | J38: フォニックスの読み書きはまだ練習中でわかりませんでした。 | K38: フォニックスの読み書きはまだ練習中でわかりませんでした。 | M38: フォニックスの読み書きはまだ練習中でわかりませんでした。 | O38: フォニックスの読み書きはまだ練習中でわかりませんでした。 | Q38: フォニックスの読み書きはまだ練習中でわかりませんでした。 | S38: フォニックスの読み書きはまだ練習中でわかりませんでした。 | U38: フォニックスの読み書きはまだ練習中でわかりませんでした。 | Y38: フォニックスの読み書きはまだ練習中でわかりませんでした。 | AA38: フォニックスの読み書きはまだ練習中でわかりませんでした。 | AC38: フォニックスの読み書きはまだ練習中でわかりませんでした。 | AE38: 1c1
B39: 30c2 | C39: 29c2 | D39: 28c2 | E39: 27c2 | F39: 26c2 | G39: 25c2 | H39: フォニックスの読み書きでは、先生の後に続いてまねをして言うことができました。 | I39: フォニックスの読み書きでは、先生の後に続いてまねをして言うことができました。 | J39: フォニックスの読み書きでは、先生の後に続いてまねをして言うことができました。 | K39: フォニックスの読み書きでは、先生の後に続いてまねをして言うことができました。 | M39: フォニックスの読み書きでは、先生の後に続いてまねをして言うことができました。 | O39: フォニックスの読み書きでは、先生の後に続いてまねをして言うことができました。 | Q39: フォニックスの読み書きでは、先生の後に続いてまねをして言うことができました。 | S39: フォニックスの読み書きでは、先生の後に続いてまねをして言うことができました。 | U39: フォニックスの読み書きでは、先生の後に続いてまねをして言うことができました。 | Y39: フォニックスの読み書きでは、先生の後に続いてまねをして言うことができました。 | AA39: フォニックスの読み書きでは、先生の後に続いてまねをして言うことができました。 | AC39: フォニックスの読み書きでは、先生の後に続いてまねをして言うことができました。 | AE39: 1c2
B40: 30c3 | C40: 29c3 | D40: 28c3 | E40: 27c3 | F40: 26c3 | G40: 25c3 | H40: フォニックスの読み書きでは、読みは良くできていました！ | I40: フォニックスの読み書きでは、読みは良くできていました！ | J40: フォニックスの読み書きでは、読みは良くできていました！ | K40: フォニックスの読み書きでは、読みは良くできていました！ | M40: フォニックスの読み書きでは、読みは良くできていました！ | O40: フォニックスの読み書きでは、読みは良くできていました！ | Q40: フォニックスの読み書きでは、読みは良くできていました！ | S40: フォニックスの読み書きでは、読みは良くできていました！ | U40: フォニックスの読み書きでは、読みは良くできていました！ | Y40: フォニックスの読み書きでは、読みは良くできていました！ | AA40: フォニックスの読み書きでは、読みは良くできていました！ | AC40: フォニックスの読み書きでは、読みは良くできていました！ | AE40: 1c3
...

Sheet category
A1: 30 | B1: cat A30.1 | C1: cat A30.2 | D1: cat A30.3 | E1: cat A30.4 | F1: cat A30.5 | G1: cat A30.6 | H1: cat A30.7 | I1: cat A30.8
A2: 29 | B2: cat A29.1 | C2: cat A29.2 | D2: cat A29.3 | E2: cat A29.4 | F2: cat A29.5 | G2: cat A29.6 | H2: cat A29.7 | I2: cat A29.8
A3: 28 | B3: cat A28.1 | C3: cat A28.2 | D3: cat A28.3 | E3: cat A28.4 | F3: cat A28.5 | G3: cat A28.6 | H3: cat A28.7 | I3: cat A28.8
A4: 27 | B4: cat A27.1 | C4: cat A27.2 | D4: cat A27.3 | E4: cat A27.4 | F4: cat A27.5 | G4: cat A27.6 | H4: cat A27.7 | I4: cat A27.8
A5: 26 | B5: cat A26.1 | C5: cat A26.2 | D5: cat A26.3 | E5: cat A26.4 | F5: cat A26.5 | G5: cat A26.6 | H5: cat A26.7 | I5: cat A26.8
A6: 25 | B6: cat A25.1 | C6: cat A25.2 | D6: cat A25.3 | E6: cat A25.4 | F6: cat A25.5 | G6: cat A25.6 | H6: cat A25.7 | I6: cat A25.8
A7: 24 | B7: あいさつ [Hello] | C7: 自分の名前 [Name] | D7: フォニックスの歌 [Phonics Song] | E7: 色 [Colors] | F7: 乗り物 [Vehicles] | G7: 虫 [Insects] | H7: フォニックス [phonics] | I7: ライティング [writing]
A8: 23 | B8: あいさつ [Greetings]（名前 / 年れい / 感情表現 ） | C8: 花 [Flowers] | D8: 野菜 [Vegetables] | E8: おもちゃ [toys] | F8: Question [How many] | G8: Question [How much] | H8: フォニックス [phonics] | I8: ライティング [writing]
A9: 22 | B9: あいさつ [Greetings]（名前 / 年れい / 感情表現 ） | C9: 食べ物 1[Food] | D9: 持ち物1[Belongings] | E9: キッチン周りの道具[Kitchen Utencils] | F9: 食べ物2[Food] | G9: 持ち物2[Belongings] | H9: フォニックス [phonics] | I9: ライティング [writing]
A10: 21 | B10: あいさつ [Greetings]（名前 / 年れい / 感情表現 ） | C10: 曜日 [The Days of The Week] | D10: 反対言葉 [Opposite] | E10: 天気 [Weather] | F10: 衣類１ [Clothes 1] | G10: 衣類２ [Clothes 2] | H10: フォニックス [phonics] | I10: ライティング [writing]
A11: 20 | B11: 声の大きさ [Voice] | C11: すらすら言える [Fluency] | D11: 発音 [Pronunciation] | E11: 暗記 [Memorization] | F11: 内容 [Content] | G11: ジェスチャー [Gesture] | H11: 顔の表情や目線 [Facial Expressions, Eyes] | I11: 態度 [Atittude]
A12: 19 | B12: あいさつ [Greetings]（名前 / 年れい / 感情表現 / 天気） | C12: 楽器 [Musical Instruments] | D12: スポーツ [Sports] | E12: 動詞1 [Verbs] | F12: 動詞2 [Verbs] | G12: 家族・性格 [Family/Personality] | H12: フォニックス [phonics] | I12: ライティング [writing]
... A30: 1 | B30: cat A1.1 | C30: cat A1.2 | D30: cat A1.3 | E30: cat A1.4 | F30: cat A1.5 | G30: cat A1.6 | H30: cat A1.7 | I30: cat A1.8
